log/output_300_2021_CNN_gpu0.log
wandb: Currently logged in as: pqy000 (pqythu). Use `wandb login --relogin` to force relogin
GPU device ID: 0
newdata/300_2021.npy
2024-09-06 17:26:26.861644: I tensorflow/core/platform/cpu_feature_guard.cc:193] This TensorFlow binary is optimized with oneAPI Deep Neural Network Library (oneDNN) to use the following CPU instructions in performance-critical operations:  AVX2 FMA
To enable them in other operations, rebuild TensorFlow with the appropriate compiler flags.
2024-09-06 17:26:27.924886: W tensorflow/compiler/xla/stream_executor/platform/default/dso_loader.cc:64] Could not load dynamic library 'libnvinfer.so.7'; dlerror: libnvinfer.so.7: cannot open shared object file: No such file or directory; LD_LIBRARY_PATH: /opt/cudnn/lib64:/usr/local/cuda/lib64
2024-09-06 17:26:27.925005: W tensorflow/compiler/xla/stream_executor/platform/default/dso_loader.cc:64] Could not load dynamic library 'libnvinfer_plugin.so.7'; dlerror: libnvinfer_plugin.so.7: cannot open shared object file: No such file or directory; LD_LIBRARY_PATH: /opt/cudnn/lib64:/usr/local/cuda/lib64
2024-09-06 17:26:27.925018: W tensorflow/compiler/tf2tensorrt/utils/py_utils.cc:38] TF-TRT Warning: Cannot dlopen some TensorRT libraries. If you would like to use Nvidia GPU with TensorRT, please make sure the missing libraries mentioned above are installed properly.
wandb: Tracking run with wandb version 0.12.17
wandb: Run data is saved locally in /home/qingyi/GPU20/DeepLOB/wandb/run-20240906_172618-3pzomtfq
wandb: Run `wandb offline` to turn off syncing.
wandb: Syncing run CNN
wandb: ⭐️ View project at https://wandb.ai/pqythu/futures300
wandb: 🚀 View run at https://wandb.ai/pqythu/futures300/runs/3pzomtfq
Model(
  (conv1): Conv1d(10, 64, kernel_size=(3,), stride=(1,), padding=(1,))
  (conv2): Conv1d(64, 64, kernel_size=(3,), stride=(1,), padding=(1,))
  (pool): MaxPool1d(kernel_size=2, stride=2, padding=0, dilation=1, ceil_mode=False)
  (fc): Linear(in_features=512, out_features=5, bias=True)
)
number of parameters: 16901
Training start
epoch  1 | time used:  1.56s | train_loss 1.520 | valid loss 1.736 | valid acc 0.165 | mae 1.510 | mse 2.860 | rmse 1.69 | r2 -0.00 | sharp 2.06
epoch  2 | time used:  0.20s | train_loss 1.772 | valid loss 1.573 | valid acc 0.330 | mae 2.012 | mse 6.908 | rmse 2.63 | r2 -1.42 | sharp 0.00
epoch  3 | time used:  0.18s | train_loss 1.509 | valid loss 1.573 | valid acc 0.330 | mae 2.012 | mse 6.908 | rmse 2.63 | r2 -1.42 | sharp 0.00
epoch  4 | time used:  0.16s | train_loss 1.506 | valid loss 1.573 | valid acc 0.330 | mae 2.012 | mse 6.908 | rmse 2.63 | r2 -1.42 | sharp 0.00
epoch  5 | time used:  0.16s | train_loss 1.504 | valid loss 1.573 | valid acc 0.330 | mae 2.012 | mse 6.908 | rmse 2.63 | r2 -1.42 | sharp 0.00
epoch  6 | time used:  0.17s | train_loss 1.504 | valid loss 1.573 | valid acc 0.330 | mae 2.012 | mse 6.908 | rmse 2.63 | r2 -1.42 | sharp 0.00
epoch  7 | time used:  0.16s | train_loss 1.505 | valid loss 1.573 | valid acc 0.330 | mae 2.012 | mse 6.908 | rmse 2.63 | r2 -1.42 | sharp 0.00
epoch  8 | time used:  0.15s | train_loss 1.504 | valid loss 1.573 | valid acc 0.330 | mae 2.012 | mse 6.908 | rmse 2.63 | r2 -1.42 | sharp 0.00
epoch  9 | time used:  0.15s | train_loss 1.519 | valid loss 1.566 | valid acc 0.345 | mae 1.988 | mse 6.812 | rmse 2.61 | r2 -1.38 | sharp 2.06
epoch 10 | time used:  0.15s | train_loss 1.559 | valid loss 1.566 | valid acc 0.345 | mae 1.988 | mse 6.812 | rmse 2.61 | r2 -1.38 | sharp 2.06
saving the model to ./save/2021_300/CNN/checkpoint10.pt
epoch 11 | time used:  0.17s | train_loss 1.559 | valid loss 1.566 | valid acc 0.345 | mae 1.988 | mse 6.812 | rmse 2.61 | r2 -1.38 | sharp 2.06
epoch 12 | time used:  0.15s | train_loss 1.540 | valid loss 1.573 | valid acc 0.330 | mae 2.012 | mse 6.908 | rmse 2.63 | r2 -1.42 | sharp 0.00
epoch 13 | time used:  0.15s | train_loss 1.505 | valid loss 1.573 | valid acc 0.330 | mae 2.012 | mse 6.908 | rmse 2.63 | r2 -1.42 | sharp 0.00
epoch 14 | time used:  0.15s | train_loss 1.505 | valid loss 1.573 | valid acc 0.330 | mae 2.012 | mse 6.908 | rmse 2.63 | r2 -1.42 | sharp 0.00
epoch 15 | time used:  0.15s | train_loss 1.507 | valid loss 1.573 | valid acc 0.330 | mae 2.012 | mse 6.908 | rmse 2.63 | r2 -1.42 | sharp 0.00
epoch 16 | time used:  0.17s | train_loss 1.506 | valid loss 1.573 | valid acc 0.330 | mae 2.012 | mse 6.908 | rmse 2.63 | r2 -1.42 | sharp 0.00
epoch 17 | time used:  0.15s | train_loss 1.648 | valid loss 1.736 | valid acc 0.165 | mae 1.510 | mse 2.860 | rmse 1.69 | r2 -0.00 | sharp 2.06
epoch 18 | time used:  0.15s | train_loss 1.734 | valid loss 1.736 | valid acc 0.165 | mae 1.510 | mse 2.860 | rmse 1.69 | r2 -0.00 | sharp 2.06
epoch 19 | time used:  0.15s | train_loss 1.648 | valid loss 1.573 | valid acc 0.330 | mae 2.012 | mse 6.908 | rmse 2.63 | r2 -1.42 | sharp 0.00
epoch 20 | time used:  0.15s | train_loss 1.504 | valid loss 1.573 | valid acc 0.330 | mae 2.012 | mse 6.908 | rmse 2.63 | r2 -1.42 | sharp 0.00
saving the model to ./save/2021_300/CNN/checkpoint20.pt
epoch 21 | time used:  0.15s | train_loss 1.506 | valid loss 1.573 | valid acc 0.330 | mae 2.012 | mse 6.908 | rmse 2.63 | r2 -1.42 | sharp 0.00
epoch 22 | time used:  0.16s | train_loss 1.505 | valid loss 1.573 | valid acc 0.330 | mae 2.012 | mse 6.908 | rmse 2.63 | r2 -1.42 | sharp 0.00
epoch 23 | time used:  0.18s | train_loss 1.552 | valid loss 1.566 | valid acc 0.345 | mae 1.988 | mse 6.812 | rmse 2.61 | r2 -1.38 | sharp 2.06
epoch 24 | time used:  0.18s | train_loss 1.552 | valid loss 1.566 | valid acc 0.345 | mae 1.988 | mse 6.812 | rmse 2.61 | r2 -1.38 | sharp 2.06
epoch 25 | time used:  0.17s | train_loss 1.564 | valid loss 1.566 | valid acc 0.345 | mae 1.988 | mse 6.812 | rmse 2.61 | r2 -1.38 | sharp 2.06
epoch 26 | time used:  0.16s | train_loss 1.720 | valid loss 1.834 | valid acc 0.071 | mae 1.678 | mse 3.836 | rmse 1.96 | r2 -0.34 | sharp 2.06
epoch 27 | time used:  0.15s | train_loss 1.813 | valid loss 1.736 | valid acc 0.165 | mae 1.510 | mse 2.860 | rmse 1.69 | r2 -0.00 | sharp 2.06
epoch 28 | time used:  0.15s | train_loss 1.713 | valid loss 1.573 | valid acc 0.330 | mae 2.012 | mse 6.908 | rmse 2.63 | r2 -1.42 | sharp 0.00
epoch 29 | time used:  0.15s | train_loss 1.506 | valid loss 1.573 | valid acc 0.330 | mae 2.012 | mse 6.908 | rmse 2.63 | r2 -1.42 | sharp 0.00
epoch 30 | time used:  0.15s | train_loss 1.504 | valid loss 1.573 | valid acc 0.330 | mae 2.012 | mse 6.908 | rmse 2.63 | r2 -1.42 | sharp 0.00
saving the model to ./save/2021_300/CNN/checkpoint30.pt
epoch 31 | time used:  0.15s | train_loss 1.557 | valid loss 1.566 | valid acc 0.345 | mae 1.988 | mse 6.812 | rmse 2.61 | r2 -1.38 | sharp 2.06
epoch 32 | time used:  0.15s | train_loss 1.560 | valid loss 1.566 | valid acc 0.345 | mae 1.988 | mse 6.812 | rmse 2.61 | r2 -1.38 | sharp 2.06
epoch 33 | time used:  0.16s | train_loss 1.559 | valid loss 1.566 | valid acc 0.345 | mae 1.988 | mse 6.812 | rmse 2.61 | r2 -1.38 | sharp 2.06
epoch 34 | time used:  0.15s | train_loss 1.558 | valid loss 1.566 | valid acc 0.345 | mae 1.988 | mse 6.812 | rmse 2.61 | r2 -1.38 | sharp 2.06
epoch 35 | time used:  0.16s | train_loss 1.559 | valid loss 1.566 | valid acc 0.345 | mae 1.988 | mse 6.812 | rmse 2.61 | r2 -1.38 | sharp 2.06
epoch 36 | time used:  0.15s | train_loss 1.514 | valid loss 1.573 | valid acc 0.330 | mae 2.012 | mse 6.908 | rmse 2.63 | r2 -1.42 | sharp 0.00
epoch 37 | time used:  0.15s | train_loss 1.506 | valid loss 1.573 | valid acc 0.330 | mae 2.012 | mse 6.908 | rmse 2.63 | r2 -1.42 | sharp 0.00
epoch 38 | time used:  0.16s | train_loss 1.537 | valid loss 1.573 | valid acc 0.330 | mae 2.012 | mse 6.908 | rmse 2.63 | r2 -1.42 | sharp 0.00
epoch 39 | time used:  0.16s | train_loss 1.531 | valid loss 1.573 | valid acc 0.330 | mae 2.012 | mse 6.908 | rmse 2.63 | r2 -1.42 | sharp 0.00
epoch 40 | time used:  0.17s | train_loss 1.519 | valid loss 1.573 | valid acc 0.330 | mae 2.012 | mse 6.908 | rmse 2.63 | r2 -1.42 | sharp 0.00
